Parsing RDF facts from  facts.n3
Traceback (most recent call last):
  File "/Users/armen/.pythonbrew/venvs/Python-2.7.2/socialwebhack/bin/FuXi", line 8, in <module>
    load_entry_point('FuXi==1.3.production', 'console_scripts', 'FuXi')()
  File "/Users/armen/.pythonbrew/venvs/Python-2.7.2/socialwebhack/lib/python2.7/site-packages/FuXi-1.3.production-py2.7.egg/FuXi/Rete/CommandLine.py", line 290, in main
    factGraph.parse(fileN,format=options.inputFormat)
  File "build/bdist.macosx-10.6-x86_64/egg/rdflib/Graph.py", line 711, in parse
  File "build/bdist.macosx-10.6-x86_64/egg/rdflib/Graph.py", line 692, in prepare_input_source
  File "build/bdist.macosx-10.6-x86_64/egg/rdflib/URLInputSource.py", line 21, in __init__
  File "/Users/armen/.pythonbrew/pythons/Python-2.7.2/lib/python2.7/urllib2.py", line 126, in urlopen
    return _opener.open(url, data, timeout)
  File "/Users/armen/.pythonbrew/pythons/Python-2.7.2/lib/python2.7/urllib2.py", line 394, in open
    response = self._open(req, data)
  File "/Users/armen/.pythonbrew/pythons/Python-2.7.2/lib/python2.7/urllib2.py", line 412, in _open
    '_open', req)
  File "/Users/armen/.pythonbrew/pythons/Python-2.7.2/lib/python2.7/urllib2.py", line 372, in _call_chain
    result = func(*args)
  File "/Users/armen/.pythonbrew/pythons/Python-2.7.2/lib/python2.7/urllib2.py", line 1302, in file_open
    return self.open_local_file(req)
  File "/Users/armen/.pythonbrew/pythons/Python-2.7.2/lib/python2.7/urllib2.py", line 1342, in open_local_file
    raise URLError(msg)
urllib2.URLError: <urlopen error [Errno 2] No such file or directory: '/Users/armen/dev/semantic-inference-engine/2'>
